<?xml version="1.0" ?>
<robot name="panda" xmlns:xacro="http://www.ros.org/wiki/xacro">
  <link name="base_link"/>
  <joint name="panda_fixed" type="fixed">
    <origin rpy="0 0 0.0" xyz="0 0 0.0"/>
    <parent link="base_link"/>
    <child link="panda_link0"/>
    <axis xyz="0 0 0"/>
  </joint>

  <link name="panda_link0">
    <visual>
      <geometry>
        <mesh filename="meshes/visual/link0.dae"/>
      </geometry>
    </visual>
    <collision>
      <geometry>
        <mesh filename="meshes/collision/link0.obj"/>
      </geometry>
    </collision>


  </link>
  <link name="panda_link1">
    <visual>
      <geometry>
        <mesh filename="meshes/visual/link1.dae"/>
      </geometry>
    </visual>
    <collision>
      <geometry>
        <mesh filename="meshes/collision/link1.obj"/>
      </geometry>
    </collision>
    <inertial>
      <origin rpy="0 0 0" xyz="0.00033 -0.02204 -0.04762"/>
      <mass value="2.797"/>
      <inertia ixx="0.0156" ixy="0.0" ixz="0.0" iyy="0.01439" iyz="-0.0024" izz="0.005"/>
    </inertial>
  </link>
  <joint name="panda_joint1" type="revolute">
    <safety_controller k_position="100.0" k_velocity="40.0" soft_lower_limit="-2.8973" soft_upper_limit="2.8973"/>
    <origin rpy="0 0 0" xyz="0 0 0.333"/>
    <parent link="panda_link0"/>
    <child link="panda_link1"/>
    <axis xyz="0 0 1"/>
    <dynamics damping="10.0"/>
    <limit effort="87" lower="-2.8973" upper="2.8973" velocity="2.1750"/>
  </joint>
  <link name="panda_link2">
    <visual>
      <geometry>
        <mesh filename="meshes/visual/link2.dae"/>
      </geometry>
    </visual>
    <collision>
      <geometry>
        <mesh filename="meshes/collision/link2.obj"/>
      </geometry>
    </collision>
    <inertial>
      <origin rpy="0 0 0" xyz="0.00038 -0.09211 0.01908"/>
      <mass value="2.542"/>
      <inertia ixx="0.0166" ixy="0.0" ixz="0.0" iyy="0.0046" iyz="0.0035" izz="0.015"/>
    </inertial>
  </link>
  <joint name="panda_joint2" type="revolute">
    <safety_controller k_position="100.0" k_velocity="40.0" soft_lower_limit="-1.7628" soft_upper_limit="1.7628"/>
    <origin rpy="-1.57079632679 0 0" xyz="0 0 0"/>
    <parent link="panda_link1"/>
    <child link="panda_link2"/>
    <axis xyz="0 0 1"/>
    <dynamics damping="10.0"/>
    <limit effort="87" lower="-1.7628" upper="1.7628" velocity="2.1750"/>
  </joint>
  <link name="panda_link3">
    <visual>
      <geometry>
        <mesh filename="meshes/visual/link3.dae"/>
      </geometry>
    </visual>
    <collision>
      <geometry>
        <mesh filename="meshes/collision/link3.obj"/>
      </geometry>
    </collision>
    <inertial>
      <origin rpy="0 0 0" xyz="0.05152 0.01696 -0.02971"/>
      <mass value="2.2513"/>
      <inertia ixx="0.006" ixy="0.009" ixz="0.003" iyy="0.0086" iyz="0.009" izz="0.0065"/>
    </inertial>
  </link>
  <joint name="panda_joint3" type="revolute">
    <safety_controller k_position="100.0" k_velocity="40.0" soft_lower_limit="-2.8973" soft_upper_limit="2.8973"/>
    <origin rpy="1.57079632679 0 0" xyz="0 -0.316 0"/>
    <parent link="panda_link2"/>
    <child link="panda_link3"/>
    <axis xyz="0 0 1"/>
    <dynamics damping="10.0"/>
    <limit effort="87" lower="-2.8973" upper="2.8973" velocity="2.1750"/>
  </joint>
  <link name="panda_link4">
    <visual>
      <geometry>
        <mesh filename="meshes/visual/link4.dae"/>
      </geometry>
    </visual>
    <collision>
      <geometry>
        <mesh filename="meshes/collision/link4.obj"/>
      </geometry>
    </collision>
    <inertial>
      <origin rpy="0 0 0" xyz="-0.05113 0.05825 0.01698"/>
      <mass value="2.2037"/>
      <inertia ixx="0.0156" ixy="0.0" ixz="0.0" iyy="0.01439" iyz="-0.0024" izz="0.005"/>
    </inertial>
  </link>
  <joint name="panda_joint4" type="revolute">
    <safety_controller k_position="100.0" k_velocity="40.0" soft_lower_limit="-3.0718" soft_upper_limit="-0.0698"/>
    <origin rpy="1.57079632679 0 0" xyz="0.0825 0 0"/>
    <parent link="panda_link3"/>
    <child link="panda_link4"/>
    <axis xyz="0 0 1"/>
    <dynamics damping="10.0"/>
    <limit effort="87" lower="-3.0718" upper="-0.0698" velocity="2.1750"/>
    <!-- something is weird with this joint limit config
    <dynamics damping="10.0"/>
    <limit effort="87" lower="-3.0" upper="0.087" velocity="2.1750"/>  -->
  </joint>
  <link name="panda_link5">
    <visual>
      <geometry>
        <mesh filename="meshes/visual/link5.dae"/>
      </geometry>
    </visual>
    <collision>
      <geometry>
        <mesh filename="meshes/collision/link5.obj"/>
      </geometry>
    </collision>
    <inertial>
      <origin rpy="0 0 0" xyz="-0.00005 0.03730 -0.09280"/>
      <mass value="2.2855"/>
      <inertia ixx="0.02297014781" ixy="0.0" ixz="0.0" iyy="0.02095060919" iyz="0.00382345782" izz="0.00430606551"/>
    </inertial>
  </link>
  <joint name="panda_joint5" type="revolute">
    <safety_controller k_position="100.0" k_velocity="40.0" soft_lower_limit="-2.8973" soft_upper_limit="2.8973"/>
    <origin rpy="-1.57079632679 0 0" xyz="-0.0825 0.384 0"/>
    <parent link="panda_link4"/>
    <child link="panda_link5"/>
    <axis xyz="0 0 1"/>
    <dynamics damping="10.0"/>
    <limit effort="12" lower="-2.8973" upper="2.8973" velocity="2.6100"/>
  </joint>
  <link name="panda_link6">
    <visual>
      <geometry>
        <mesh filename="meshes/visual/link6.dae"/>
      </geometry>
    </visual>
    <collision>
      <geometry>
        <mesh filename="meshes/collision/link6.obj"/>
      </geometry>
    </collision>
    <inertial>
      <origin rpy="0 0 0" xyz="0.06572 -0.00371 0.00153"/>
      <mass value="1.353"/>
      <inertia ixx="0.00087964522" ixy="-0.00021487814" ixz="-0.00011911662" iyy="0.00277796968" iyz="0.00001274322" izz="0.00286701969"/>
    </inertial>
  </link>
  <joint name="panda_joint6" type="revolute">
    <safety_controller k_position="100.0" k_velocity="40.0" soft_lower_limit="-0.0175" soft_upper_limit="3.7525"/>
    <origin rpy="1.57079632679 0 0" xyz="0 0 0"/>
    <parent link="panda_link5"/>
    <child link="panda_link6"/>
    <axis xyz="0 0 1"/>
    <dynamics damping="10.0"/>
    <limit effort="12" lower="-0.0175" upper="3.7525" velocity="2.6100"/>
    <!-- <dynamics damping="10.0"/>
    <limit effort="12" lower="-0.0873" upper="3.0" velocity="2.6100"/> -->
  </joint>

  <link name="panda_link7">
    <visual>
      <geometry>
        <mesh filename="meshes/visual/link7.dae"/>
      </geometry>
    </visual>
    <collision>
      <geometry>
        <mesh filename="meshes/collision/link7.obj"/>
      </geometry>
    </collision>
        <inertial>
      <origin rpy="0 0 0" xyz="0.00089 -0.00044 0.05491"/>
      <mass value="0.35973"/>
      <inertia ixx="0.00019541063" ixy="0.00000165231" ixz="0.00000148826" iyy="0.00019210361" iyz="-0.00000131132" izz="0.00017936256"/>
    </inertial>
  </link>
  <joint name="panda_joint7" type="revolute">
    <safety_controller k_position="100.0" k_velocity="40.0" soft_lower_limit="-2.8973" soft_upper_limit="2.8973"/>
    <origin rpy="1.57079632679 0 0" xyz="0.088 0 0"/>
    <parent link="panda_link6"/>
    <child link="panda_link7"/>
    <axis xyz="0 0 1"/>
    <dynamics damping="10.0"/>
    <limit effort="12" lower="-2.8973" upper="2.8973" velocity="2.6100"/>
  </joint>

  <!-- Removed some links, refer to: https://www.notion.so/cuRobo-Env-Setup-27761dabb12d8012ae92fa235d83df65?source=copy_link#27a61dabb12d804d95b8d8e505076810 -->

  <!-- Camera Links and Joints -->
  <!-- Camera 1 on panda_link2 -->
  <link name="cam1_link">
    <inertial>
      <mass value="0.01"/>
      <inertia ixx="0.00001" ixy="0.0" ixz="0.0" iyy="0.00001" iyz="0.0" izz="0.00001"/>
      <origin rpy="0 0 0" xyz="0 0 0"/>
    </inertial>
  </link>
  <joint name="cam1_joint" type="fixed">
    <origin rpy="0 1.5707963 3.1415927" xyz="0.055 -0.07 0.0535"/>  <!-- t done, ori done -->
    <parent link="panda_link2"/>
    <child link="cam1_link"/>
  </joint>

  <!-- Camera 2 on panda_link3 -->
  <link name="cam2_link">
    <inertial>
      <mass value="0.01"/>
      <inertia ixx="0.00001" ixy="0.0" ixz="0.0" iyy="0.00001" iyz="0.0" izz="0.00001"/>
      <origin rpy="0 0 0" xyz="0 0 0"/>
    </inertial>
  </link>
  <joint name="cam2_joint" type="fixed">
    <origin rpy="1.5707963 0 0" xyz="0.1 0.11 0"/>  <!-- t done, ori done -->
    <parent link="panda_link3"/>
    <child link="cam2_link"/>
  </joint>

  <!-- Camera 3 on panda_link4 -->
  <link name="cam3_link">
    <inertial>
      <mass value="0.01"/>
      <inertia ixx="0.00001" ixy="0.0" ixz="0.0" iyy="0.00001" iyz="0.0" izz="0.00001"/>
      <origin rpy="0 0 0" xyz="0 0 0"/>
    </inertial>
  </link>
  <joint name="cam3_joint" type="fixed">
    <origin rpy="0 3.1415927 0" xyz="0 0 0.11"/>  <!-- t done, ori done -->
    <parent link="panda_link4"/>
    <child link="cam3_link"/>
  </joint>

  <!-- Camera 4 on panda_link5 -->
  <link name="cam4_link">
    <inertial>
      <mass value="0.01"/>
      <inertia ixx="0.00001" ixy="0.0" ixz="0.0" iyy="0.00001" iyz="0.0" izz="0.00001"/>
      <origin rpy="0 0 0" xyz="0.05 0 0"/>
    </inertial>
  </link>
  <joint name="cam4_joint" type="fixed">
    <origin rpy="1.5707963 0 0 " xyz="0 0.105 -0.120"/>  <!-- t done, ori done -->
    <parent link="panda_link5"/>
    <child link="cam4_link"/>
  </joint>

  <!-- Camera 5 on panda_link5 (second camera on same link) -->
  <link name="cam5_link">
    <inertial>
      <mass value="0.01"/>
      <inertia ixx="0.00001" ixy="0.0" ixz="0.0" iyy="0.00001" iyz="0.0" izz="0.00001"/>
      <origin rpy="0 0 0" xyz="0 0 0"/>
    </inertial>
  </link>
  <joint name="cam5_joint" type="fixed">
    <origin rpy="1.5707963 0 -1.5707963" xyz="0.050 0.040 -0.120"/>  <!-- t done, ori done -->
    <parent link="panda_link5"/>
    <child link="cam5_link"/>
  </joint>

  <!-- Camera 6 on panda_link6 -->
  <link name="cam6_link">
    <inertial>
      <mass value="0.01"/>
      <inertia ixx="0.00001" ixy="0.0" ixz="0.0" iyy="0.00001" iyz="0.0" izz="0.00001"/>
      <origin rpy="0 0 0" xyz="0 0 0"/>
    </inertial>
  </link>
  <joint name="cam6_joint" type="fixed">
    <origin rpy="0 3.1415927 0" xyz="0 0 0.055"/>  <!-- t done, ori done -->
    <parent link="panda_link6"/>
    <child link="cam6_link"/>
  </joint>

  <!-- Camera 7 on panda_link7 -->
  <link name="cam7_link">
    <inertial>
      <mass value="0.01"/>
      <inertia ixx="0.00001" ixy="0.0" ixz="0.0" iyy="0.00001" iyz="0.0" izz="0.00001"/>
      <origin rpy="0 0 0" xyz="0 0 0"/>
    </inertial>
  </link>
  <joint name="cam7_joint" type="fixed">
    <origin rpy="-1.5707963 0 1.5707963" xyz="0.045 0 0"/>  <!-- t done, ori done -->
    <parent link="panda_link7"/>
    <child link="cam7_link"/>
  </joint>


</robot>








